[2025-06-14T01:55:01.006+0000] {local_task_job_runner.py:123} INFO - ::group::Pre task execution logs
[2025-06-14T01:55:01.023+0000] {taskinstance.py:2612} INFO - Dependencies all met for dep_context=non-requeueable deps ti=<TaskInstance: fetch_stock_options.fetch_data scheduled__2025-06-14T01:50:00+00:00 [queued]>
[2025-06-14T01:55:01.031+0000] {taskinstance.py:2612} INFO - Dependencies all met for dep_context=requeueable deps ti=<TaskInstance: fetch_stock_options.fetch_data scheduled__2025-06-14T01:50:00+00:00 [queued]>
[2025-06-14T01:55:01.032+0000] {taskinstance.py:2865} INFO - Starting attempt 1 of 4
[2025-06-14T01:55:01.057+0000] {taskinstance.py:2888} INFO - Executing <Task(HttpOperator): fetch_data> on 2025-06-14 01:50:00+00:00
[2025-06-14T01:55:01.065+0000] {standard_task_runner.py:72} INFO - Started process 794 to run task
[2025-06-14T01:55:01.070+0000] {standard_task_runner.py:104} INFO - Running: ['***', 'tasks', 'run', 'fetch_stock_options', 'fetch_data', 'scheduled__2025-06-14T01:50:00+00:00', '--job-id', '7', '--raw', '--subdir', 'DAGS_FOLDER/fetch_stock_options.py', '--cfg-path', '/tmp/tmpuzv1v7l0']
[2025-06-14T01:55:01.075+0000] {standard_task_runner.py:105} INFO - Job 7: Subtask fetch_data
[2025-06-14T01:55:01.122+0000] {task_command.py:467} INFO - Running <TaskInstance: fetch_stock_options.fetch_data scheduled__2025-06-14T01:50:00+00:00 [running]> on host 8234d234fb87
[2025-06-14T01:55:01.186+0000] {taskinstance.py:3131} INFO - Exporting env vars: AIRFLOW_CTX_DAG_OWNER='***' AIRFLOW_CTX_DAG_ID='fetch_stock_options' AIRFLOW_CTX_TASK_ID='fetch_data' AIRFLOW_CTX_EXECUTION_DATE='2025-06-14T01:50:00+00:00' AIRFLOW_CTX_TRY_NUMBER='1' AIRFLOW_CTX_DAG_RUN_ID='scheduled__2025-06-14T01:50:00+00:00'
[2025-06-14T01:55:01.188+0000] {taskinstance.py:731} INFO - ::endgroup::
[2025-06-14T01:55:01.200+0000] {http.py:173} INFO - Calling HTTP method
[2025-06-14T01:55:01.210+0000] {taskinstance.py:3310} ERROR - Task failed with exception
Traceback (most recent call last):
  File "/home/airflow/.local/lib/python3.9/site-packages/airflow/models/taskinstance.py", line 767, in _execute_task
    result = _execute_callable(context=context, **execute_callable_kwargs)
  File "/home/airflow/.local/lib/python3.9/site-packages/airflow/models/taskinstance.py", line 733, in _execute_callable
    return ExecutionCallableRunner(
  File "/home/airflow/.local/lib/python3.9/site-packages/airflow/utils/operator_helpers.py", line 252, in run
    return self.func(*args, **kwargs)
  File "/home/airflow/.local/lib/python3.9/site-packages/airflow/models/baseoperator.py", line 406, in wrapper
    return func(self, *args, **kwargs)
  File "/home/airflow/.local/lib/python3.9/site-packages/airflow/providers/http/operators/http.py", line 170, in execute
    return self.execute_sync(context=context)
  File "/home/airflow/.local/lib/python3.9/site-packages/airflow/providers/http/operators/http.py", line 179, in execute_sync
    response = self.hook.run(self.endpoint, self.data, self.headers, self.extra_options)
  File "/home/airflow/.local/lib/python3.9/site-packages/airflow/providers/http/operators/http.py", line 152, in hook
    conn = BaseHook.get_connection(conn_id)
  File "/home/airflow/.local/lib/python3.9/site-packages/airflow/hooks/base.py", line 83, in get_connection
    conn = Connection.get_connection_from_secrets(conn_id)
  File "/home/airflow/.local/lib/python3.9/site-packages/airflow/models/connection.py", line 537, in get_connection_from_secrets
    raise AirflowNotFoundException(f"The conn_id `{conn_id}` isn't defined")
airflow.exceptions.AirflowNotFoundException: The conn_id `data_collector_service` isn't defined
[2025-06-14T01:55:01.217+0000] {taskinstance.py:1225} INFO - Marking task as UP_FOR_RETRY. dag_id=fetch_stock_options, task_id=fetch_data, run_id=scheduled__2025-06-14T01:50:00+00:00, execution_date=20250614T015000, start_date=20250614T015501, end_date=20250614T015501
[2025-06-14T01:55:01.235+0000] {taskinstance.py:340} INFO - ::group::Post task execution logs
[2025-06-14T01:55:01.243+0000] {standard_task_runner.py:124} ERROR - Failed to execute job 7 for task fetch_data (The conn_id `data_collector_service` isn't defined; 794)
Traceback (most recent call last):
  File "/home/airflow/.local/lib/python3.9/site-packages/airflow/task/task_runner/standard_task_runner.py", line 117, in _start_by_fork
    ret = args.func(args, dag=self.dag)
  File "/home/airflow/.local/lib/python3.9/site-packages/airflow/cli/cli_config.py", line 49, in command
    return func(*args, **kwargs)
  File "/home/airflow/.local/lib/python3.9/site-packages/airflow/utils/cli.py", line 115, in wrapper
    return f(*args, **kwargs)
  File "/home/airflow/.local/lib/python3.9/site-packages/airflow/cli/commands/task_command.py", line 483, in task_run
    task_return_code = _run_task_by_selected_method(args, _dag, ti)
  File "/home/airflow/.local/lib/python3.9/site-packages/airflow/cli/commands/task_command.py", line 256, in _run_task_by_selected_method
    return _run_raw_task(args, ti)
  File "/home/airflow/.local/lib/python3.9/site-packages/airflow/cli/commands/task_command.py", line 341, in _run_raw_task
    return ti._run_raw_task(
  File "/home/airflow/.local/lib/python3.9/site-packages/airflow/utils/session.py", line 97, in wrapper
    return func(*args, session=session, **kwargs)
  File "/home/airflow/.local/lib/python3.9/site-packages/airflow/models/taskinstance.py", line 3004, in _run_raw_task
    return _run_raw_task(
  File "/home/airflow/.local/lib/python3.9/site-packages/airflow/models/taskinstance.py", line 273, in _run_raw_task
    TaskInstance._execute_task_with_callbacks(
  File "/home/airflow/.local/lib/python3.9/site-packages/airflow/models/taskinstance.py", line 3158, in _execute_task_with_callbacks
    result = self._execute_task(context, task_orig)
  File "/home/airflow/.local/lib/python3.9/site-packages/airflow/models/taskinstance.py", line 3182, in _execute_task
    return _execute_task(self, context, task_orig)
  File "/home/airflow/.local/lib/python3.9/site-packages/airflow/models/taskinstance.py", line 767, in _execute_task
    result = _execute_callable(context=context, **execute_callable_kwargs)
  File "/home/airflow/.local/lib/python3.9/site-packages/airflow/models/taskinstance.py", line 733, in _execute_callable
    return ExecutionCallableRunner(
  File "/home/airflow/.local/lib/python3.9/site-packages/airflow/utils/operator_helpers.py", line 252, in run
    return self.func(*args, **kwargs)
  File "/home/airflow/.local/lib/python3.9/site-packages/airflow/models/baseoperator.py", line 406, in wrapper
    return func(self, *args, **kwargs)
  File "/home/airflow/.local/lib/python3.9/site-packages/airflow/providers/http/operators/http.py", line 170, in execute
    return self.execute_sync(context=context)
  File "/home/airflow/.local/lib/python3.9/site-packages/airflow/providers/http/operators/http.py", line 179, in execute_sync
    response = self.hook.run(self.endpoint, self.data, self.headers, self.extra_options)
  File "/home/airflow/.local/lib/python3.9/site-packages/airflow/providers/http/operators/http.py", line 152, in hook
    conn = BaseHook.get_connection(conn_id)
  File "/home/airflow/.local/lib/python3.9/site-packages/airflow/hooks/base.py", line 83, in get_connection
    conn = Connection.get_connection_from_secrets(conn_id)
  File "/home/airflow/.local/lib/python3.9/site-packages/airflow/models/connection.py", line 537, in get_connection_from_secrets
    raise AirflowNotFoundException(f"The conn_id `{conn_id}` isn't defined")
airflow.exceptions.AirflowNotFoundException: The conn_id `data_collector_service` isn't defined
[2025-06-14T01:55:01.288+0000] {local_task_job_runner.py:266} INFO - Task exited with return code 1
[2025-06-14T01:55:01.351+0000] {taskinstance.py:3900} INFO - 0 downstream tasks scheduled from follow-on schedule check
[2025-06-14T01:55:01.355+0000] {local_task_job_runner.py:245} INFO - ::endgroup::
